<?xml version="1.0" ?>
<robot name="LISM_Arm">
    <link name="world"/>

    <joint name="worldTolink1" type="fixed">
        <parent link="world"/>
        <child link="link1"/>
        <origin xyz="0.0 0.0 0.0"/>
    </joint>
    
    <link name="link1">
        <visual>
            <origin rpy="0.0 0.0 0.0" xyz="0 0 1.1"/>
            <geometry>
                <cylinder length="0.2" radius="0.02"/>
            </geometry>
        </visual>
    </link>

    <joint name="link1_link2" type="prismatic">
        <origin rpy="0 0 0" xyz="0.0 0 1.0"/>
        <parent link="link1"/>
        <child link="link2"/>
        <axis xyz="0 0 1"/>
    </joint>

    <link name="link2">
        <visual>
            <origin rpy="0.0 0.0 0.0" xyz="0.0 0 -0.05"/>
            <geometry>
                <cylinder length="0.1" radius="0.02"/>
            </geometry>
        </visual>
        <inertial>
            <mass value="0.01"/>
            <inertia ixx="0.000025" ixy="0" ixz="0" iyy="0.000025" iyz="0" izz="0.000025"/>
        </inertial>
    </link>

    <joint name="link2_link3" type="prismatic">
        <origin rpy="0 0 0" xyz="0.0 0 -0.1"/>
        <parent link="link2"/>
        <child link="link3"/>
        <axis xyz="0 0 1"/>
    </joint>

    <link name="link3">
        <inertial>
            <mass value="0.01"/>
            <inertia ixx="0.000025" ixy="0" ixz="0" iyy="0.000025" iyz="0" izz="0.000025"/>
        </inertial>
        <visual>
            <origin rpy="0.0 0.0 0.0" xyz="0.0 0 -0.1"/>
            <geometry>
                <cylinder length="0.2" radius="0.02"/>
            </geometry>
        </visual>
    </link>

    <joint name="link3_hand" type="revolute">
        <origin rpy="0 0 0" xyz="0.0 0 -0.2"/>
        <parent link="link3"/>
        <child link="hand"/>
        <axis xyz="0 1 0"/>
    </joint>

    <link name="hand">
        <visual>
            <origin rpy="0.0 -1.57 0.0" xyz="0 0 0"/>
            <geometry>
                <mesh filename="meshes/hand.dae" scale="0.001 0.001 0.001"/>
            </geometry>
        </visual>
        <inertial>
            <mass value="0.2"/>
            <origin rpy="0.0 0.0 0.0" xyz="0 0 0"/>
            <inertia ixx="0.00267" ixy="0" ixz="0.0" iyy="0.00267" iyz="0" izz="0.00267"/>
        </inertial>
        <collision>
            <origin rpy="0.0 -1.57 0.0" xyz="0 0.0 0"/>
            <geometry>
                <mesh filename="meshes/hand.obj" scale="0.001 0.001 0.001"/> 
            </geometry>
            <material name="">
                <contact name="steel"/>
            </material>
        </collision>
    </link> 
</robot>