<?xml version="1.0" ?>
<robot name="LISM_Arm">
     <!--base of fixing arm-->
    <link name="world"/>

    <joint name="worldTobase" type="fixed">
        <parent link="world"/>
        <child link="base"/>
        <origin rpy="0 0 0" xyz="0.0 0.0 0.0"/>
    </joint>
    
    <link name="base">
        <visual>
            <origin rpy="0.0 0.0 0.0" xyz="0 0 0.01"/>
            <geometry>
                <box size = "0.2 0.3 0.02"/>
            </geometry>
        </visual>
    </link>

    <joint name="baseTojoint" type="fixed">
        <parent link="base"/>
        <child link="joint"/>
        <origin rpy="0 0 0" xyz="0.0 0.0 0.0"/>
    </joint>
    
    <link name="joint">
        <visual>
            <origin rpy="0.0 0.0 0.0" xyz="0 0 0.01"/>
            <geometry>
                <sphere radius="0.06"/>
            </geometry>
        </visual>
    </link>

    <joint name="BaseToLink" type="revolute">
        <axis xyz="-1 0 0"/>
        <origin rpy="0 0 0" xyz="0.0 0.0 0.0"/>
        <parent link="joint"/>
        <child link="link1"/>
    </joint>

    <link name="link1">
        <visual>
            <origin rpy="0.0 0.0 0.0" xyz="0 0 0.4"/>
            <geometry>
                <cylinder length="0.8" radius="0.03"/>
            </geometry>
        </visual>
        <inertial>
            <mass value="0.5"/>
            <origin rpy="0.0 0.0 0.0" xyz="0 0 0"/>
            <inertia ixx="0.1067" ixy="0" ixz="0.0" iyy="0.1067" iyz="0" izz="0.000225"/>
        </inertial>
    </link>

    <joint name="Link1ToBall1" type="fixed">
        <axis xyz="1 0 0"/>
        <origin rpy="0 0 0" xyz="0.0 0.0 0.8"/>
        <parent link="link1"/>
        <child link="ball1"/>
    </joint>
    
    <link name="ball1">
        <visual>
            <origin rpy="0.0 0.0 0.0" xyz="0 0 0.0"/>
            <geometry>
                <sphere radius="0.04"/>
            </geometry>
        </visual>
    </link>

    <joint name="Ball1ToTemp" type="fixed">
        <axis xyz="1 0 0"/>
        <origin rpy="0 0 0" xyz="0.0 0.0 0.0"/>
        <parent link="ball1"/>
        <child link="temp"/>
    </joint>    

    <link name="temp">
        <visual>
            <origin rpy="0 1.57 0.0" xyz="0.1 0 0"/>
            <geometry>
                <cylinder length="0.2" radius="0.02"/>
            </geometry>
        </visual>
    </link>

    <joint name="TempToBall2" type="fixed">
        <axis xyz="1 0 0"/>
        <origin rpy="0 0 0" xyz="0.2 0.0 0.0"/>
        <parent link="temp"/>
        <child link="ball2"/>
    </joint>
    <joint name="baseTojoint" type="fixed">
        <parent link="base"/>
        <child link="joint"/>
        <origin rpy="0 0 0" xyz="0.0 0.0 0.0"/>
    </joint>
    
    <link name="joint">
        <visual>
            <origin rpy="0.0 0.0 0.0" xyz="0 0 0.01"/>
            <geometry>
                <sphere radius="0.06"/>
            </geometry>
        </visual>
    </link>

    <joint name="BaseToLink" type="revolute">
        <axis xyz="-1 0 0"/>
        <origin rpy="0 0 0" xyz="0.0 0.0 0.0"/>
        <parent link="joint"/>
        <child link="link1"/>
    </joint>

    <link name="link1">
        <visual>
            <origin rpy="0.0 0.0 0.0" xyz="0 0 0.4"/>
            <geometry>
                <cylinder length="0.8" radius="0.03"/>
            </geometry>
        </visual>
        <inertial>
            <mass value="0.5"/>
            <origin rpy="0.0 0.0 0.0" xyz="0 0 0"/>
            <inertia ixx="0.1067" ixy="0" ixz="0.0" iyy="0.1067" iyz="0" izz="0.000225"/>
        </inertial>
    </link>

    <joint name="Link1ToBall1" type="fixed">
        <axis xyz="1 0 0"/>
        <origin rpy="0 0 0" xyz="0.0 0.0 0.8"/>
        <parent link="link1"/>
        <child link="ball1"/>
    </joint>
    
    <link name="ball1">
        <visual>
            <origin rpy="0.0 0.0 0.0" xyz="0 0 0.0"/>
            <geometry>
                <sphere radius="0.04"/>
            </geometry>
        </visual>
    </link>

    <joint name="Ball1ToTemp" type="fixed">
        <axis xyz="1 0 0"/>
        <origin rpy="0 0 0" xyz="0.0 0.0 0.0"/>
        <parent link="ball1"/>
        <child link="temp"/>
    </joint>    

    <link name="temp">
        <visual>
            <origin rpy="0 1.57 0.0" xyz="0.1 0 0"/>
            <geometry>
                <cylinder length="0.2" radius="0.02"/>
            </geometry>
        </visual>
    </link>

    <joint name="TempToBall2" type="fixed">
        <axis xyz="1 0 0"/>
        <origin rpy="0 0 0" xyz="0.2 0.0 0.0"/>
        <parent link="temp"/>
        <child link="ball2"/>
    </joint>
    
    <link name="ball2">
        <visual>
            <origin rpy="0.0 0.0 0.0" xyz="0 0 0.0"/>
            <geometry>
                <sphere radius="0.04"/>
            </geometry>
        </visual>
    </link>

    <joint name="Ball2ToLink2" type="revolute">
        <axis xyz="-1 0 0"/>
        <origin rpy="0 0 0" xyz="0.0 0.0 0"/>
        <parent link="ball2"/>
        <child link="link2"/>
    </joint>

    <link name="link2">
        <visual>f
            <origin rpy="0.0 0.0 0.0" xyz="0 0 0.0"/>
            <geometry>
                <sphere radius="0.04"/>
            </geometry>
        </visual>
    </link>

    <joint name="Ball2ToLink2" type="revolute">
        <axis xyz="-1 0 0"/>
        <origin rpy="0 0 0" xyz="0.0 0.0 0"/>
        <parent link="ball2"/>
        <child link="link2"/>
    </joint>

    <link name="link2">
        <visual>
            <origin rpy="0.0 0.0 0.0" xyz="0 0 -0.15"/>
            <geometry>
                <cylinder length="0.3" radius="0.02"/>
            </geometry>
        </visual>
        <inertial>
            <mass value="0.2"/>
            <origin rpy="0.0 0.0 0.0" xyz="0 0 0"/>
            <inertia ixx="0.006" ixy="0" ixz="0.0" iyy="0.006" iyz="0" izz="0.00004"/>
        </inertial>
    </link>

    <joint name="Link2ToBall3" type="fixed">
        <axis xyz="1 0 0"/>
        <origin rpy="0 0 0" xyz="0.0 0.0 -0.3"/>
        <parent link="link2"/>
        <child link="ball3"/>
    </joint>
    
    <link name="ball3">
        <visual>
            <origin rpy="0.0 0.0 0.0" xyz="0 0 0.0"/>
            <geometry>
                <sphere radius="0.04"/>
            </geometry>
        </visual>
    </link>

    <joint name="Ball2ToLink3" type="revolute">
        <axis xyz="-1 0 0"/>
        <origin rpy="0 0 0" xyz="0.0 0.0 0.0"/>
        <parent link="ball3"/>
        <child link="link3"/>
    </joint>

    <link name="link3">
        <visual>
            <origin rpy="0.0 0.0 0.0" xyz="0 0 -0.15"/>
            <geometry>
                <cylinder length="0.3" radius="0.02"/>
            </geometry>
        </visual>
        <inertial>
            <mass value="0.2"/>
            <origin rpy="0.0 0.0 0.0" xyz="0 0.0 0"/>
            <inertia ixx="0.006" ixy="0" ixz="0.0" iyy="0.006" iyz="0" izz="0.00004"/>
        </inertial>
    </link>

    <joint name="Link3ToBall4" type="fixed">
        <axis xyz="1 0 0"/>
        <origin rpy="0 0 0" xyz="0.0 0.0 -0.3"/>
        <parent link="link3"/>
        <child link="ball4"/>
    </joint>
    
    <link name="ball4">
        <visual>
            <origin rpy="0.0 0.0 0.0" xyz="0 0 0.0"/>
            <geometry>
                <sphere radius="0.04"/>
            </geometry>
        </visual>
    </link>

</robot>