<?xml version="1.0" ?>
<robot name="LISM_Arm">
     <!--base of fixing arm-->
    <link name="world"/>

    <joint name="worldTolink1" type="fixed">
        <parent link="world"/>
        <child link="link1"/>
        <origin xyz="0.5 0.0 0.0"/>
    </joint>
    
    <link name="link1">
        <visual>
            <origin rpy="0.0 0.0 0.0" xyz="0 0 0.5"/>
            <geometry>
                <cylinder length="1.0" radius="0.02"/>
            </geometry>
        </visual>
    </link>

    <joint name="link1_link2" type="fixed">
        <origin rpy="0 0 0" xyz="-0.25 0 1.0"/>
        <parent link="link1"/>
        <child link="link2"/>
    </joint>

    <link name="link2">
        <visual>
            <origin rpy="0.0 1.57 0.0" xyz="0.0 0 0.0"/>
            <geometry>
                <cylinder length="0.5" radius="0.02"/>
            </geometry>
        </visual>
    </link>

    <joint name="link2_link3" type="revolute">
        <origin rpy="0 0 0" xyz="-0.25 0 0.0"/>
        <axis xyz = "1 0 0"/>
        <parent link="link2"/>
        <child link="link3"/>
    </joint>

    <link name="link3">
        <visual>
            <origin rpy="0.0 0.0 0.0" xyz="0 0 -0.05"/>
            <geometry>
                <cylinder length="0.1" radius="0.02"/>
            </geometry>
        </visual>
    </link>

    <!-- <joint name="link3_link4" type="revolute">
        <axis xyz= "0 0 1"/>
        <origin rpy="0 0 0" xyz="0.0 0.0 -0.1"/>
        <parent link="link3"/>
        <child link="link4"/>
    </joint>

    <link name="link4">
        <visual>
            <origin rpy="0.0 0.0 0.0" xyz="0 0 -0.05"/>
            <geometry>
                <cylinder length="0.5" radius="0.02"/>
            </geometry>
        </visual>
    </link> -->

    <!-- <joint name="link4_link5" type="prismatic">
        <axis xyz= "0 0 1"/>
        <origin rpy="0 0 0" xyz="0.0 0 -0.1"/>
        <parent link="link4"/>
        <child link="link5"/>
    </joint>

    <link name="link5">
        <visual>
            <origin rpy="0.0 0.0 0.0" xyz="0.0 0 -0.075"/>
            <geometry>
                <cylinder length="0.15" radius="0.02"/>
            </geometry>
        </visual>
    </link> -->

    <!-- <joint name="link5_hand" type="revolute">
        <axis xyz="0 1 0"/>
        <origin rpy="0 0 0" xyz="0.0 0 -0.15"/>
        <parent link="link5"/>
        <child link="hand"/>
    </joint> -->

    <!-- <link name="hand">
        <visual>
            <origin rpy="0.0 -1.57 0.0" xyz="0 0 0"/>
            <geometry>
                <mesh filename="meshes/hand.dae" scale="0.001 0.001 0.001"/>
            </geometry>
        </visual>
        <inertial>
            <mass value="0.2"/>
            <origin rpy="0.0 0.0 0.0" xyz="0 0 0"/>
            <inertia ixx="0.00267" ixy="0" ixz="0.0" iyy="0.00267" iyz="0" izz="0.00267"/>
        </inertial>
        <collision>
            <origin rpy="0.0 -1.57 0.0" xyz="0 0.0 0"/>
            <geometry>
                <mesh filename="meshes/hand.obj" scale="0.001 0.001 0.001"/> 
            </geometry>
            <material name="">
                <contact name="steel"/>
            </material>
        </collision>
    </link> -->

    <!-- <joint name="worldToball" type="free">
        <parent link="world"/>
        <child link="ball"/>
        <origin rpy="0 0 0" xyz="0 0 0"/>
    </joint> -->

</robot>